Workbook

Sheet README
A1: 매출원가(COGS) 모델 v1 — 심장 디지털 트윈 파이프라인의 세 가지 사업 형태
A2: 작성 2026-09-16. 모든 숫자는 가정치이며 [추정]으로 표시된 것은 시장 조사가 아닌 자릿수 추정이다. Inputs 시트의 파란 글씨를 실제 값으로 바꾸면 전체가 재계산된다.
A4: 시트 구성
A5: Inputs — 인건비·재료·장비·간접비·가격 레버. 노란 칸이 결과를 가장 크게 움직이는 값.
A6: UnitCost_A — 산학 수탁 과제: 환자 1케이스(형상+팬텀+CFD+보고서) 원가 → 과제 원가·마진·용량.
A7: UnitCost_B — V&V40 규제 근거 패키지: 기기 프로그램 1건의 활동별 시간·비인건비·마진.
A8: UnitCost_C — 케이스당 시술 계획 서비스: 변동원가·공헌이익·손익분기 케이스 수.
A9: Annual_PnL — 5년 시나리오(A→B 전환). 인건비는 가동률과 무관하게 전액 비용 처리(보수적).
A10: Sensitivity — B(시간×단가), A(케이스 수×단가) 매출총이익률 표.
A12: 색 규칙: 파란 글씨 = 입력값, 검정 = 수식, 초록 = 다른 시트 참조, 노란 칸 = 핵심 레버/결과.
A14: 주의
A15: 1. 이 모델은 사업 구조를 보기 위한 추정이지 재무 자문이 아니다. 실제 장비 견적·급여·계약 단가로 바꿔야 의미가 있다.
... A18: 4. MM-WHS 등 연구용 라이선스 데이터는 상업 서비스에 쓸 수 없다. 데이터 확보 비용은 별도.

Sheet Inputs
A1: 가정치 (Inputs) — 파란 글씨는 전부 수정 가능, 노란 칸은 결과에 가장 크게 영향을 주는 레버
A2: 통화: 원(KRW). 출처 표기: [추정] = 제(Claude) 자릿수 추정, 검증된 시장 데이터 아님. 실제 견적·급여·장비가로 바꿔 쓸 것.
A3: 항목 | B3: 값 | C3: 단위 | D3: 출처 / 비고
A4: 1. 인건비
A5: 엔지니어(석사급) 연봉 | B5: 55000000 | C5: ₩/년 | D5: [추정] 국내 의공학 석사 초임~3년차 대역. 실제 채용 조건으로 교체
A6: 부대비용 배수(4대보험·퇴직급여 등) | B6: 1.2 | C6: 배 | D6: [추정] 통상 1.15~1.25
A7: 연간 청구가능(직접투입) 시간 | B7: 1600 | C7: h/년 | D7: [추정] 연 2,000h 근무 중 80%가 프로젝트 직접투입
A8: 엔지니어 시간당 원가 | B8: =Inputs!$B$5*Inputs!$B$6/Inputs!$B$7 -> 41250 | C8: ₩/h | D8: → 연봉 × 부대비용 배수 ÷ 청구가능 시간
A9: PI/시니어 자문 시간당 원가 | B9: 80000 | C9: ₩/h | D9: [추정] 교수·시니어 엔지니어 자문 단가
A10: 기술원(랩테크·프린팅 보조) 시간당 원가 | B10: 25000 | C10: ₩/h | D10: [추정]
A12: 2. 재료비 (팬텀 1개 기준)
A13: 실리콘 단가 | B13: 200000 | C13: ₩/kg | D13: [추정] Sylgard 184·Ecoflex 급 소매가 대역
A14: 팬텀당 실리콘 사용량 | B14: 1.1 | C14: kg | D14: phantom_design.json: 실리콘 0.98 L ≈ 1.06 kg + 손실
A15: PVA 필라멘트 단가 | B15: 60000 | C15: ₩/kg | D15: [추정]
A16: 코어 PVA 사용량 | B16: 0.2 | C16: kg | D16: core 173.7 mL ≈ 0.2 kg (PVA 밀도 1.2) — 서포트 포함
A17: PLA 단가 | B17: 30000 | C17: ₩/kg | D17: [추정]
A18: 주형 상자+절개 모형 PLA 사용량 | B18: 0.35 | C18: kg | D18: mould_box + 다리 + 절개 모형 1세트
A19: 피팅·튜빙·잡자재 | B19: 60000 | C19: ₩/팬텀 | D19: [추정] 3/4″·5/8″ 바브 피팅, 튜빙, 이형제, 진공 탈포 소모품
A20: 팬텀 1개 재료비 합계 | B20: =Inputs!$B$13*Inputs!$B$14+Inputs!$B$15*Inputs!$B$16+Inputs!$B$17*Inputs!$B$18+Inputs!$B$19 -> 302500 | C20: ₩ | D20: → 위 항목의 합
A22: 3. 장비 (감가상각 → 시간/주 단위 원가)
A23: FDM 프린터 가격 | B23: 3000000 | C23: ₩ | D23: [추정] PVA 듀얼 노즐급
A24: 프린터 수명(가동 시간) | B24: 5000 | C24: h | D24: [추정]
A25: 프린터 시간당 원가 | B25: =Inputs!$B$23/Inputs!$B$24 -> 600 | C25: ₩/h | D25: → 가격 ÷ 수명
A26: 워크스테이션 가격 | B26: 4000000 | C26: ₩ | D26: RTX 3060 / 32 GB 급 (사용자 보유)
A27: 워크스테이션 수명 | B27: 3 | C27: 년 | D27: [추정]
A28: 워크스테이션 연 가동 시간 | B28: 2000 | C28: h/년 | D28: [추정]
A29: 계산 시간당 원가 | B29: =Inputs!$B$26/(Inputs!$B$27*Inputs!$B$28) -> 666.66667 | C29: ₩/h | D29: → 가격 ÷ (수명 × 연 가동)
A30: 펄스 듀플리케이터 시스템(펌프·센서·유량계) | B30: 150000000 | C30: ₩ | D30: [추정] 상용 심장 유동 벤치 시스템 1~3억 대역. B 형태에만 필요
A31: 벤치 수명 | B31: 7 | C31: 년 | D31: [추정]
A32: 벤치 연 가동 주수 | B32: 40 | C32: 주/년 | D32: [추정]
A33: 벤치 주당 원가(감가상각) | B33: =Inputs!$B$30/(Inputs!$B$31*Inputs!$B$32) -> 535714.29 | C33: ₩/주 | D33: → 가격 ÷ (수명 × 연 가동 주수)
A35: 4. 간접비·예비비
A36: 간접비율 (직접인건비 대비) | B36: 0.25 | C36: % | D36: [추정] 공간·행정·소프트웨어·보험. 대학 산학과제 간접비 15~25%와 유사
A37: 예비비율 (직접원가 대비) | B37: 0.1 | C37: % | D37: [추정] 재작업·출력 실패·재캐스팅
A39: 5. 가격·규모 레버 — A. 산학 수탁 과제
A40: A 과제 단가 | B40: 30000000 | C40: ₩/과제 | D40: [추정] 국내 산학 과제 2천만~5천만 대역
A41: A 과제당 환자 케이스 수 | B41: 3 | C41: 건 | D41: [추정]
A42: A 과제당 비반복 개발(NRE) 시간 | B42: 100 | C42: h | D42: [추정] 기기·질문에 맞춘 파이프라인 개조
A43: A 과제당 미팅·보고·PM 시간 | B43: 20 | C43: h | D43: [추정]
A45: 6. 가격·규모 레버 — B. V&V40 규제 근거 패키지
...

Sheet UnitCost_A
A1: A. 산학 수탁 — 환자 1케이스 단위원가 → 과제 단위 원가·마진
A2: 케이스 = CT → 형상 파이프라인 → 팬텀 1개 → 강체벽 CFD → 보고서. 시간(h)은 파란 입력, 단가는 Inputs 참조.
A4: 활동 | B4: 시간(h) | C4: 단가(₩/h) | D4: 원가(₩) | E4: 비고
A5: CT 확보·익명화·품질 확인 | B5: 2 | C5: =Inputs!$B$8 -> 41250 | D5: =B5*C5 -> 82500 | E5: 기관 CT 또는 공개 데이터
A6: 세그멘테이션 정련(CT 재분할·QA) | B6: 3 | C6: =Inputs!$B$8 -> 41250 | D6: =B6*C6 -> 123750 | E6: ct_refine_lv.py 계열; 수동 보정 포함
A7: 형상 파이프라인 실행·검증(1~17단계) | B7: 4 | C7: =Inputs!$B$8 -> 41250 | D7: =B7*C7 -> 165000 | E7: PIPELINE.md; 대부분 자동, 검증 그림 확인
A8: 팬텀 제작 감독(출력·주형·경화·코어 용해) | B8: 6 | C8: =Inputs!$B$8 -> 41250 | D8: =B8*C8 -> 247500 | E8: 실제 경과시간은 3~4일, 투입시간만 계상
A9: 팬텀 제작 보조(기술원) | B9: 6 | C9: =Inputs!$B$10 -> 25000 | D9: =B9*C9 -> 150000 | E9: 출력 교체·탈포·세척
A10: CFD 케이스 설정·실행·후처리 | B10: 12 | C10: =Inputs!$B$8 -> 41250 | D10: =B10*C10 -> 495000 | E10: OpenFOAM/svMultiPhysics 강체벽
A11: 보고서 작성 | B11: 8 | C11: =Inputs!$B$8 -> 41250 | D11: =B11*C11 -> 330000 | E11: 형상·팬텀·CFD 결과·불확실성
A12: PI 검토 | B12: 2 | C12: =Inputs!$B$9 -> 80000 | D12: =B12*C12 -> 160000
A13: 직접인건비 소계 | B13: =SUM(B5:B12) -> 43 | D13: =SUM(D5:D12) -> 1753750
A15: 비인건비 항목 | B15: 수량 | C15: 단가(₩) | D15: 원가(₩) | E15: 비고
A16: 팬텀 재료(실리콘·PVA·PLA·피팅) | B16: 1 | C16: =Inputs!$B$20 -> 302500 | D16: =B16*C16 -> 302500 | E16: Inputs §2 합계
A17: 프린터 가동(코어+상자+절개 모형) | B17: 45 | C17: =Inputs!$B$25 -> 600 | D17: =B17*C17 -> 27000 | E17: [추정] 출력 시간 45 h
A18: 계산(워크스테이션) 가동 | B18: 30 | C18: =Inputs!$B$29 -> 666.66667 | D18: =B18*C18 -> 20000 | E18: [추정] CFD 3주기 + 메시
A19: 비인건비 소계 | D19: =SUM(D16:D18) -> 349500
A21: 직접원가 (인건비+비인건비) | D21: =D13+D19 -> 2103250
A22: 간접비 (직접인건비 × 간접비율) | D22: =D13*Inputs!$B$36 -> 438437.5
A23: 예비비 (직접원가 × 예비비율) | D23: =D21*Inputs!$B$37 -> 210325
A24: 케이스 1건 매출원가 (COGS) | D24: =D21+D22+D23 -> 2752012.5
A26: 과제 단위 (Inputs §5)
A27: 항목 | B27: 수량 | C27: 단가(₩) | D27: 원가(₩) | E27: 비고
A28: 케이스 원가 × 케이스 수 | B28: =Inputs!$B$41 -> 3 | C28: =D24 -> 2752012.5 | D28: =B28*C28 -> 8256037.5
A29: 비반복 개발(NRE) 인건비 | B29: =Inputs!$B$42 -> 100 | C29: =Inputs!$B$8*(1+Inputs!$B$36) -> 51562.5 | D29: =B29*C29 -> 5156250 | E29: 간접비 포함 단가
A30: 미팅·보고·PM 인건비 | B30: =Inputs!$B$43 -> 20 | C30: =Inputs!$B$8*(1+Inputs!$B$36) -> 51562.5 | D30: =B30*C30 -> 1031250
A31: 과제 매출원가 합계 | D31: =SUM(D28:D30) -> 14443538
A32: 과제 단가(매출) | D32: =Inputs!$B$40 -> 30000000
A33: 매출총이익 | D33: =D32-D31 -> 15556462
A34: 매출총이익률 | D34: =IF(D32=0,0,(D32-D31)/D32) -> 0.51854875
A35: 과제당 총 투입 시간(h) | D35: =Inputs!$B$41*B13+Inputs!$B$42+Inputs!$B$43 -> 249
A36: 엔지니어 1인 연간 최대 과제 수 | D36: =IF(D35=0,0,Inputs!$B$7/D35) -> 6.4257028 | E36: → 청구가능 시간 ÷ 과제당 시간 (용량 상한)
A38: 해석: 매출총이익률이 높아 보이지만, 이 형태에서 '이익'은 곧 연구실 인건비·장비 재투자다. 용량 상한(연 과제 수)이 매출을 결정한다.

Sheet UnitCost_B
A1: B. V&V40 규제 근거 패키지 — 기기 프로그램 1건 원가·마진
A2: 범위: 환자 형상 N개 + 짝지어진 팬텀 N개 + 벤치 캠페인 + in silico(FSI/EM) 모델·보정·불확실성 정량화 + 신뢰성 보고서. 시간은 파란 입력.
A4: 활동(엔지니어 시간) | B4: 시간(h) | C4: 단가(₩/h) | D4: 원가(₩) | E4: 비고
A5: 형상 파이프라인 × N (형상당 9 h) | B5: =9*Inputs!$B$47 -> 45 | C5: =Inputs!$B$8 -> 41250 | D5: =B5*C5 -> 1856250 | E5: 형상 수는 Inputs §6
A6: 팬텀 제작 감독 × N (팬텀당 6 h) | B6: =6*Inputs!$B$47 -> 30 | C6: =Inputs!$B$8 -> 41250 | D6: =B6*C6 -> 1237500
A7: 벤치 셋업·교정 | B7: 40 | C7: =Inputs!$B$8 -> 41250 | D7: =B7*C7 -> 1650000
A8: 벤치 시험 (N 팬텀 × 3 조건 × 4 h) | B8: =12*Inputs!$B$47 -> 60 | C8: =Inputs!$B$8 -> 41250 | D8: =B8*C8 -> 2475000 | E8: 정상·고박출·저박출 등
A9: 벤치 데이터 분석 | B9: 60 | C9: =Inputs!$B$8 -> 41250 | D9: =B9*C9 -> 2475000
A10: in silico 모델 구축(메시·BC·정합 메시) | B10: 160 | C10: =Inputs!$B$8 -> 41250 | D10: =B10*C10 -> 6600000 | E10: svMultiPhysics FSI 또는 EM
A11: 모델 보정(벤치 대비) | B11: 140 | C11: =Inputs!$B$8 -> 41250 | D11: =B11*C11 -> 5775000
A12: 불확실성 정량화·민감도(20~30 런 설정·분석) | B12: 160 | C12: =Inputs!$B$8 -> 41250 | D12: =B12*C12 -> 6600000 | E12: V&V40 신뢰성 요소
A13: V&V40 신뢰성 문서·보고서 | B13: 240 | C13: =Inputs!$B$8 -> 41250 | D13: =B13*C13 -> 9900000 | E13: 가장 큰 항목 — 규제 어휘로 작성
A14: 독립 QA 검토 | B14: 60 | C14: =Inputs!$B$8 -> 41250 | D14: =B14*C14 -> 2475000
A15: PM·고객 미팅 | B15: 60 | C15: =Inputs!$B$8 -> 41250 | D15: =B15*C15 -> 2475000
A16: 엔지니어 시간 소계 | B16: =SUM(B5:B15) -> 1055 | D16: =SUM(D5:D15) -> 43518750
A17: 기술원 시간 (팬텀당 6 h + 벤치 보조 40 h) | B17: =6*Inputs!$B$47+40 -> 70 | C17: =Inputs!$B$10 -> 25000 | D17: =B17*C17 -> 1750000
A18: PI/시니어 시간 | B18: =Inputs!$B$48 -> 80 | C18: =Inputs!$B$9 -> 80000 | D18: =B18*C18 -> 6400000
A19: 직접인건비 합계 | D19: =D16+D17+D18 -> 51668750
A21: 비인건비 항목 | B21: 수량 | C21: 단가(₩) | D21: 원가(₩) | E21: 비고
A22: 팬텀 재료 × N | B22: =Inputs!$B$47 -> 5 | C22: =Inputs!$B$20 -> 302500 | D22: =B22*C22 -> 1512500
A23: 프린터 가동 (팬텀당 45 h) | B23: =45*Inputs!$B$47 -> 225 | C23: =Inputs!$B$25 -> 600 | D23: =B23*C23 -> 135000
A24: 벤치 점유 (주) | B24: =Inputs!$B$49 -> 6 | C24: =Inputs!$B$33 -> 535714.29 | D24: =B24*C24 -> 3214285.7 | E24: 감가상각 배분 — 장비가 없으면 외부 벤치 임차비로 교체
A25: 벤치 소모품 | B25: 1 | C25: =Inputs!$B$51 -> 1500000 | D25: =B25*C25 -> 1500000
A26: 계산 가동 (FSI/EM 런 + UQ) | B26: 600 | C26: =Inputs!$B$29 -> 666.66667 | D26: =B26*C26 -> 400000 | E26: [추정] 24 h 런 × 25회. 원가는 작고 달력 시간이 병목
A27: 규제 자문 외주 | B27: 1 | C27: =Inputs!$B$50 -> 5000000 | D27: =B27*C27 -> 5000000
A28: 비인건비 소계 | D28: =SUM(D22:D27) -> 11761786
A30: 직접원가 | D30: =D19+D28 -> 63430536
A31: 간접비 (직접인건비 × 간접비율) | D31: =D19*Inputs!$B$36 -> 12917188
A32: 예비비 (직접원가 × 예비비율) | D32: =D30*Inputs!$B$37 -> 6343053.6
A33: 프로그램 매출원가 (COGS) | D33: =D30+D31+D32 -> 82690777
A34: 프로그램 단가(매출) | D34: =Inputs!$B$46 -> 200000000
A35: 매출총이익 | D35: =D34-D33 -> 1.1730922e+08
A36: 매출총이익률 | D36: =IF(D34=0,0,(D34-D33)/D34) -> 0.58654612
A37: 프로그램당 총 인력 시간(h) | D37: =B16+B17+B18 -> 1205
A38: 엔지니어 3인 팀 연간 최대 프로그램 수 | D38: =IF(B16=0,0,3*Inputs!$B$7/B16) -> 4.549763 | E38: → 3 × 청구가능 시간 ÷ 프로그램당 엔지니어 시간
A40: 해석: 원가의 70% 이상이 인건비이고 그중 최대 항목은 문서화다. 파이프라인 자동화가 줄이는 것은 형상·팬텀 시간(전체의 ~10%)뿐 — 마진의 열쇠는 문서 템플릿 재사용이다.

Sheet UnitCost_C
A1: C. 케이스당 시술 계획 서비스 — 변동원가·공헌이익·손익분기
A2: 전제: SaMD 인허가 완료 후 운영 단계. 고정비·초기투자가 지배적이라 손익분기 케이스 수가 핵심.
A4: 케이스당 변동원가
A5: 엔지니어 검토 인건비 | B5: =Inputs!$B$55*Inputs!$B$8 -> 123750
A6: 클라우드·스토리지 | B6: =Inputs!$B$56 -> 10000
A7: 계산 (케이스당 4 h) | B7: =4*Inputs!$B$29 -> 2666.6667
A8: 간접비 (인건비 × 간접비율) | B8: =B5*Inputs!$B$36 -> 30937.5
A9: 케이스당 변동원가 합계 | B9: =SUM(B5:B8) -> 167354.17
A10: 케이스 단가 | B10: =Inputs!$B$54 -> 1000000
A11: 케이스당 공헌이익 | B11: =B10-B9 -> 832645.83
A12: 공헌이익률 | B12: =IF(B10=0,0,B11/B10) -> 0.83264583
A14: 연간 고정비 (SaMD 유지·QMS·보험) | B14: =Inputs!$B$57 -> 300000000
A15: 초기 투자 연 상각 | B15: =Inputs!$B$58/Inputs!$B$59 -> 100000000
A16: 연간 고정비 합계 | B16: =B14+B15 -> 400000000
A17: 손익분기 케이스 수 (연) | B17: =IF(B11<=0,0,B16/B11) -> 480.39633
A19: 연간 케이스 수 → | B19: 200 | C19: 400 | D19: 600 | E19: 800 | F19: 1000 | G19: 1500
A20: 매출 | B20: =B$19*$B$10 -> 200000000 | C20: =C$19*$B$10 -> 400000000 | D20: =D$19*$B$10 -> 600000000 | E20: =E$19*$B$10 -> 800000000 | F20: =F$19*$B$10 -> 1000000000 | G20: =G$19*$B$10 -> 1500000000
A21: 변동원가 | B21: =B$19*$B$9 -> 33470833 | C21: =C$19*$B$9 -> 66941667 | D21: =D$19*$B$9 -> 100412500 | E21: =E$19*$B$9 -> 1.3388333e+08 | F21: =F$19*$B$9 -> 1.6735417e+08 | G21: =G$19*$B$9 -> 251031250
A22: 고정비 합계 | B22: =$B$16 -> 400000000 | C22: =$B$16 -> 400000000 | D22: =$B$16 -> 400000000 | E22: =$B$16 -> 400000000 | F22: =$B$16 -> 400000000 | G22: =$B$16 -> 400000000
A23: 영업이익 | B23: =B20-B21-B22 -> -2.3347083e+08 | C23: =C20-C21-C22 -> -66941667 | D23: =D20-D21-D22 -> 99587500 | E23: =E20-E21-E22 -> 2.6611667e+08 | F23: =F20-F21-F22 -> 4.3264583e+08 | G23: =G20-G21-G22 -> 848968750
A24: 필요 엔지니어 수 (검토 시간 기준) | B24: =B$19*Inputs!$B$55/Inputs!$B$7 -> 0.375 | C24: =C$19*Inputs!$B$55/Inputs!$B$7 -> 0.75 | D24: =D$19*Inputs!$B$55/Inputs!$B$7 -> 1.125 | E24: =E$19*Inputs!$B$55/Inputs!$B$7 -> 1.5 | F24: =F$19*Inputs!$B$55/Inputs!$B$7 -> 1.875 | G24: =G$19*Inputs!$B$55/Inputs!$B$7 -> 2.8125
A26: 해석: 공헌이익률은 높지만 손익분기 케이스 수가 국내 대상 시술 건수의 상당 비율이다. 수가 없이 병원이 부담하는 구조에서는 이 케이스 수에 도달하기 어렵다.

Sheet Annual_PnL
A1: 연간 손익 시나리오 (A → B 전환, C 제외)
A2: 파란 행이 시나리오 레버. 인건비는 가동률과 무관하게 전액 비용(급여) 처리 — 미청구 시간이 곧 손실이라는 현실 반영. 원가 시트의 인건비는 여기서 이중 계상하지 않고 '비인건비 직접원가'만 가져온다.
A4: 항목 | B4: 1년차 | C4: 2년차 | D4: 3년차 | E4: 4년차 | F4: 5년차 | G4: 비고
A5: 시나리오 레버
A6: A 과제 수(건/년) | B6: 2 | C6: 3 | D6: 3 | E6: 2 | F6: 2 | G6: [시나리오] 연구실 단계 → B로 무게 이동
A7: B 프로그램 수(건/년) | B7: 0 | C7: 0 | D7: 1 | E7: 2 | F7: 3 | G7: [시나리오] 검증 논문·벤치 확보 후 3년차부터
A8: 엔지니어 인원(FTE) | B8: 1 | C8: 1.5 | D8: 3 | E8: 3 | F8: 4 | G8: [시나리오] 급여는 전액 비용
A9: 기술원 인원(FTE) | B9: 0 | C9: 0.5 | D9: 1 | E9: 1 | F9: 1
A10: 기타 고정비(임차·행정·SW·보험, ₩/년) | B10: 30000000 | C10: 40000000 | D10: 80000000 | E10: 90000000 | F10: 100000000
A11: 벤치 장비 보유(1=있음) | B11: 0 | C11: 1 | D11: 1 | E11: 1 | F11: 1 | G11: 2년차 구매 가정 → 감가상각 시작
A13: 손익
A14: 매출 — A | B14: =B6*Inputs!$B$40 -> 60000000 | C14: =C6*Inputs!$B$40 -> 90000000 | D14: =D6*Inputs!$B$40 -> 90000000 | E14: =E6*Inputs!$B$40 -> 60000000 | F14: =F6*Inputs!$B$40 -> 60000000
A15: 매출 — B | B15: =B7*Inputs!$B$46 -> 0 | C15: =C7*Inputs!$B$46 -> 0 | D15: =D7*Inputs!$B$46 -> 200000000 | E15: =E7*Inputs!$B$46 -> 400000000 | F15: =F7*Inputs!$B$46 -> 600000000
A16: 매출 합계 | B16: =B14+B15 -> 60000000 | C16: =C14+C15 -> 90000000 | D16: =D14+D15 -> 290000000 | E16: =E14+E15 -> 460000000 | F16: =F14+F15 -> 660000000
A17: 비인건비 직접원가 — A | B17: =B6*UnitCost_A!$D$19*Inputs!$B$41*(1+Inputs!$B$37) -> 2306700 | C17: =C6*UnitCost_A!$D$19*Inputs!$B$41*(1+Inputs!$B$37) -> 3460050 | D17: =D6*UnitCost_A!$D$19*Inputs!$B$41*(1+Inputs!$B$37) -> 3460050 | E17: =E6*UnitCost_A!$D$19*Inputs!$B$41*(1+Inputs!$B$37) -> 2306700 | F17: =F6*UnitCost_A!$D$19*Inputs!$B$41*(1+Inputs!$B$37) -> 2306700 | G17: 재료·프린터·계산 (인건비 제외) + 예비비
A18: 비인건비 직접원가 — B | B18: =B7*UnitCost_B!$D$28*(1+Inputs!$B$37) -> 0 | C18: =C7*UnitCost_B!$D$28*(1+Inputs!$B$37) -> 0 | D18: =D7*UnitCost_B!$D$28*(1+Inputs!$B$37) -> 12937964 | E18: =E7*UnitCost_B!$D$28*(1+Inputs!$B$37) -> 25875929 | F18: =F7*UnitCost_B!$D$28*(1+Inputs!$B$37) -> 38813893 | G18: 벤치 감가상각 배분은 아래 감가상각과 중복되므로 여기서는 제외하지 않음 — 보수적
A19: 인건비 (엔지니어·기술원 급여) | B19: =B8*Inputs!$B$5*Inputs!$B$6+B9*Inputs!$B$10*2000 -> 66000000 | C19: =C8*Inputs!$B$5*Inputs!$B$6+C9*Inputs!$B$10*2000 -> 124000000 | D19: =D8*Inputs!$B$5*Inputs!$B$6+D9*Inputs!$B$10*2000 -> 248000000 | E19: =E8*Inputs!$B$5*Inputs!$B$6+E9*Inputs!$B$10*2000 -> 248000000 | F19: =F8*Inputs!$B$5*Inputs!$B$6+F9*Inputs!$B$10*2000 -> 314000000 | G19: 기술원은 시급 × 2,000 h
A20: PI/시니어 자문 | B20: =(B6*2+B7*Inputs!$B$48)*Inputs!$B$9 -> 320000 | C20: =(C6*2+C7*Inputs!$B$48)*Inputs!$B$9 -> 480000 | D20: =(D6*2+D7*Inputs!$B$48)*Inputs!$B$9 -> 6880000 | E20: =(E6*2+E7*Inputs!$B$48)*Inputs!$B$9 -> 13120000 | F20: =(F6*2+F7*Inputs!$B$48)*Inputs!$B$9 -> 19520000 | G20: A 과제당 2 h, B 프로그램당 Inputs 시간
A21: 기타 고정비 | B21: =B10 -> 30000000 | C21: =C10 -> 40000000 | D21: =D10 -> 80000000 | E21: =E10 -> 90000000 | F21: =F10 -> 100000000
A22: 감가상각 (벤치·프린터·워크스테이션) | B22: =B11*Inputs!$B$30/Inputs!$B$31+Inputs!$B$23/5+Inputs!$B$26/Inputs!$B$27 -> 1933333.3 | C22: =C11*Inputs!$B$30/Inputs!$B$31+Inputs!$B$23/5+Inputs!$B$26/Inputs!$B$27 -> 23361905 | D22: =D11*Inputs!$B$30/Inputs!$B$31+Inputs!$B$23/5+Inputs!$B$26/Inputs!$B$27 -> 23361905 | E22: =E11*Inputs!$B$30/Inputs!$B$31+Inputs!$B$23/5+Inputs!$B$26/Inputs!$B$27 -> 23361905 | F22: =F11*Inputs!$B$30/Inputs!$B$31+Inputs!$B$23/5+Inputs!$B$26/Inputs!$B$27 -> 23361905 | G22: 프린터 5년 정액
A23: 비용 합계 | B23: =B17+B18+B19+B20+B21+B22 -> 1.0056003e+08 | C23: =C17+C18+C19+C20+C21+C22 -> 1.9130195e+08 | D23: =D17+D18+D19+D20+D21+D22 -> 3.7463992e+08 | E23: =E17+E18+E19+E20+E21+E22 -> 4.0266453e+08 | F23: =F17+F18+F19+F20+F21+F22 -> 4.980025e+08
A24: 영업이익 | B24: =B16-B23 -> -40560033 | C24: =C16-C23 -> -1.0130195e+08 | D24: =D16-D23 -> -84639919 | E24: =E16-E23 -> 57335467 | F24: =F16-F23 -> 1.619975e+08
A25: 영업이익률 | B25: =IF(B16=0,0,B24/B16) -> -0.67600056 | C25: =IF(C16=0,0,C24/C16) -> -1.1255773 | D25: =IF(D16=0,0,D24/D16) -> -0.29186179 | E25: =IF(E16=0,0,E24/E16) -> 0.12464232 | F25: =IF(F16=0,0,F24/F16) -> 0.24545076
A26: 누적 영업이익 | B26: =B24 -> -40560033 | C26: =B26+C24 -> -1.4186199e+08 | D26: =C26+D24 -> -2.2650191e+08 | E26: =D26+E24 -> -1.6916644e+08 | F26: =E26+F24 -> -7168938.1
A28: 용량 점검
A29: 필요 엔지니어 시간(h) | B29: =B6*UnitCost_A!$D$35+B7*UnitCost_B!$B$16 -> 498 | C29: =C6*UnitCost_A!$D$35+C7*UnitCost_B!$B$16 -> 747 | D29: =D6*UnitCost_A!$D$35+D7*UnitCost_B!$B$16 -> 1802 | E29: =E6*UnitCost_A!$D$35+E7*UnitCost_B!$B$16 -> 2608 | F29: =F6*UnitCost_A!$D$35+F7*UnitCost_B!$B$16 -> 3663
A30: 가용 엔지니어 시간(h) | B30: =B8*Inputs!$B$7 -> 1600 | C30: =C8*Inputs!$B$7 -> 2400 | D30: =D8*Inputs!$B$7 -> 4800 | E30: =E8*Inputs!$B$7 -> 4800 | F30: =F8*Inputs!$B$7 -> 6400
A31: 가동률 | B31: =IF(B30=0,0,B29/B30) -> 0.31125 | C31: =IF(C30=0,0,C29/C30) -> 0.31125 | D31: =IF(D30=0,0,D29/D30) -> 0.37541667 | E31: =IF(E30=0,0,E29/E30) -> 0.54333333 | F31: =IF(F30=0,0,F29/F30) -> 0.57234375 | G31: 100% 초과 = 인원 부족(시나리오 비현실), 60% 미만 = 유휴 인건비
A33: 해석: 영업이익은 거의 전적으로 B 프로그램 수와 인원의 가동률로 결정된다. A만으로는 인건비를 넘기 어렵고, B가 연 2건 이상일 때 흑자 구간에 들어간다(가정치 기준).

Sheet Sensitivity
A1: 민감도 — B 프로그램 매출총이익률: 엔지니어 시간 × 단가
A2: 행 = 프로그램당 엔지니어 시간(h), 열 = 프로그램 단가(₩). 비인건비·기술원·PI·간접비·예비비는 UnitCost_B 그대로 (시간에 비례하는 항목은 인건비·간접비).
A4: 시간(h) \ 단가(₩) | B4: 100000000 | C4: 150000000 | D4: 200000000 | E4: 300000000 | F4: 400000000
A5: 800 | B5: =IF(B$4=0,0,(B$4-(($A5*Inputs!$B$8+UnitCost_B!$D$17+UnitCost_B!$D$18+UnitCost_B!$D$28)*(1+Inputs!$B$37)+($A5*Inputs!$B$8+UnitCost_B!$D$17+UnitCost_B!$D$18)*Inputs!$B$36))/B$4) -> 0.31509536 | C5: =IF(C$4=0,0,(C$4-(($A5*Inputs!$B$8+UnitCost_B!$D$17+UnitCost_B!$D$18+UnitCost_B!$D$28)*(1+Inputs!$B$37)+($A5*Inputs!$B$8+UnitCost_B!$D$17+UnitCost_B!$D$18)*Inputs!$B$36))/C$4) -> 0.5433969 | D5: =IF(D$4=0,0,(D$4-(($A5*Inputs!$B$8+UnitCost_B!$D$17+UnitCost_B!$D$18+UnitCost_B!$D$28)*(1+Inputs!$B$37)+($A5*Inputs!$B$8+UnitCost_B!$D$17+UnitCost_B!$D$18)*Inputs!$B$36))/D$4) -> 0.65754768 | E5: =IF(E$4=0,0,(E$4-(($A5*Inputs!$B$8+UnitCost_B!$D$17+UnitCost_B!$D$18+UnitCost_B!$D$28)*(1+Inputs!$B$37)+($A5*Inputs!$B$8+UnitCost_B!$D$17+UnitCost_B!$D$18)*Inputs!$B$36))/E$4) -> 0.77169845 | F5: =IF(F$4=0,0,(F$4-(($A5*Inputs!$B$8+UnitCost_B!$D$17+UnitCost_B!$D$18+UnitCost_B!$D$28)*(1+Inputs!$B$37)+($A5*Inputs!$B$8+UnitCost_B!$D$17+UnitCost_B!$D$18)*Inputs!$B$36))/F$4) -> 0.82877384
A6: 1000 | B6: =IF(B$4=0,0,(B$4-(($A6*Inputs!$B$8+UnitCost_B!$D$17+UnitCost_B!$D$18+UnitCost_B!$D$28)*(1+Inputs!$B$37)+($A6*Inputs!$B$8+UnitCost_B!$D$17+UnitCost_B!$D$18)*Inputs!$B$36))/B$4) -> 0.20372036 | C6: =IF(C$4=0,0,(C$4-(($A6*Inputs!$B$8+UnitCost_B!$D$17+UnitCost_B!$D$18+UnitCost_B!$D$28)*(1+Inputs!$B$37)+($A6*Inputs!$B$8+UnitCost_B!$D$17+UnitCost_B!$D$18)*Inputs!$B$36))/C$4) -> 0.4691469 | D6: =IF(D$4=0,0,(D$4-(($A6*Inputs!$B$8+UnitCost_B!$D$17+UnitCost_B!$D$18+UnitCost_B!$D$28)*(1+Inputs!$B$37)+($A6*Inputs!$B$8+UnitCost_B!$D$17+UnitCost_B!$D$18)*Inputs!$B$36))/D$4) -> 0.60186018 | E6: =IF(E$4=0,0,(E$4-(($A6*Inputs!$B$8+UnitCost_B!$D$17+UnitCost_B!$D$18+UnitCost_B!$D$28)*(1+Inputs!$B$37)+($A6*Inputs!$B$8+UnitCost_B!$D$17+UnitCost_B!$D$18)*Inputs!$B$36))/E$4) -> 0.73457345 | F6: =IF(F$4=0,0,(F$4-(($A6*Inputs!$B$8+UnitCost_B!$D$17+UnitCost_B!$D$18+UnitCost_B!$D$28)*(1+Inputs!$B$37)+($A6*Inputs!$B$8+UnitCost_B!$D$17+UnitCost_B!$D$18)*Inputs!$B$36))/F$4) -> 0.80093009
A7: 1200 | B7: =IF(B$4=0,0,(B$4-(($A7*Inputs!$B$8+UnitCost_B!$D$17+UnitCost_B!$D$18+UnitCost_B!$D$28)*(1+Inputs!$B$37)+($A7*Inputs!$B$8+UnitCost_B!$D$17+UnitCost_B!$D$18)*Inputs!$B$36))/B$4) -> 0.092345357 | C7: =IF(C$4=0,0,(C$4-(($A7*Inputs!$B$8+UnitCost_B!$D$17+UnitCost_B!$D$18+UnitCost_B!$D$28)*(1+Inputs!$B$37)+($A7*Inputs!$B$8+UnitCost_B!$D$17+UnitCost_B!$D$18)*Inputs!$B$36))/C$4) -> 0.3948969 | D7: =IF(D$4=0,0,(D$4-(($A7*Inputs!$B$8+UnitCost_B!$D$17+UnitCost_B!$D$18+UnitCost_B!$D$28)*(1+Inputs!$B$37)+($A7*Inputs!$B$8+UnitCost_B!$D$17+UnitCost_B!$D$18)*Inputs!$B$36))/D$4) -> 0.54617268 | E7: =IF(E$4=0,0,(E$4-(($A7*Inputs!$B$8+UnitCost_B!$D$17+UnitCost_B!$D$18+UnitCost_B!$D$28)*(1+Inputs!$B$37)+($A7*Inputs!$B$8+UnitCost_B!$D$17+UnitCost_B!$D$18)*Inputs!$B$36))/E$4) -> 0.69744845 | F7: =IF(F$4=0,0,(F$4-(($A7*Inputs!$B$8+UnitCost_B!$D$17+UnitCost_B!$D$18+UnitCost_B!$D$28)*(1+Inputs!$B$37)+($A7*Inputs!$B$8+UnitCost_B!$D$17+UnitCost_B!$D$18)*Inputs!$B$36))/F$4) -> 0.77308634
A8: 1500 | B8: =IF(B$4=0,0,(B$4-(($A8*Inputs!$B$8+UnitCost_B!$D$17+UnitCost_B!$D$18+UnitCost_B!$D$28)*(1+Inputs!$B$37)+($A8*Inputs!$B$8+UnitCost_B!$D$17+UnitCost_B!$D$18)*Inputs!$B$36))/B$4) -> -0.074717143 | C8: =IF(C$4=0,0,(C$4-(($A8*Inputs!$B$8+UnitCost_B!$D$17+UnitCost_B!$D$18+UnitCost_B!$D$28)*(1+Inputs!$B$37)+($A8*Inputs!$B$8+UnitCost_B!$D$17+UnitCost_B!$D$18)*Inputs!$B$36))/C$4) -> 0.2835219 | D8: =IF(D$4=0,0,(D$4-(($A8*Inputs!$B$8+UnitCost_B!$D$17+UnitCost_B!$D$18+UnitCost_B!$D$28)*(1+Inputs!$B$37)+($A8*Inputs!$B$8+UnitCost_B!$D$17+UnitCost_B!$D$18)*Inputs!$B$36))/D$4) -> 0.46264143 | E8: =IF(E$4=0,0,(E$4-(($A8*Inputs!$B$8+UnitCost_B!$D$17+UnitCost_B!$D$18+UnitCost_B!$D$28)*(1+Inputs!$B$37)+($A8*Inputs!$B$8+UnitCost_B!$D$17+UnitCost_B!$D$18)*Inputs!$B$36))/E$4) -> 0.64176095 | F8: =IF(F$4=0,0,(F$4-(($A8*Inputs!$B$8+UnitCost_B!$D$17+UnitCost_B!$D$18+UnitCost_B!$D$28)*(1+Inputs!$B$37)+($A8*Inputs!$B$8+UnitCost_B!$D$17+UnitCost_B!$D$18)*Inputs!$B$36))/F$4) -> 0.73132071
A9: 1800 | B9: =IF(B$4=0,0,(B$4-(($A9*Inputs!$B$8+UnitCost_B!$D$17+UnitCost_B!$D$18+UnitCost_B!$D$28)*(1+Inputs!$B$37)+($A9*Inputs!$B$8+UnitCost_B!$D$17+UnitCost_B!$D$18)*Inputs!$B$36))/B$4) -> -0.24177964 | C9: =IF(C$4=0,0,(C$4-(($A9*Inputs!$B$8+UnitCost_B!$D$17+UnitCost_B!$D$18+UnitCost_B!$D$28)*(1+Inputs!$B$37)+($A9*Inputs!$B$8+UnitCost_B!$D$17+UnitCost_B!$D$18)*Inputs!$B$36))/C$4) -> 0.1721469 | D9: =IF(D$4=0,0,(D$4-(($A9*Inputs!$B$8+UnitCost_B!$D$17+UnitCost_B!$D$18+UnitCost_B!$D$28)*(1+Inputs!$B$37)+($A9*Inputs!$B$8+UnitCost_B!$D$17+UnitCost_B!$D$18)*Inputs!$B$36))/D$4) -> 0.37911018 | E9: =IF(E$4=0,0,(E$4-(($A9*Inputs!$B$8+UnitCost_B!$D$17+UnitCost_B!$D$18+UnitCost_B!$D$28)*(1+Inputs!$B$37)+($A9*Inputs!$B$8+UnitCost_B!$D$17+UnitCost_B!$D$18)*Inputs!$B$36))/E$4) -> 0.58607345 | F9: =IF(F$4=0,0,(F$4-(($A9*Inputs!$B$8+UnitCost_B!$D$17+UnitCost_B!$D$18+UnitCost_B!$D$28)*(1+Inputs!$B$37)+($A9*Inputs!$B$8+UnitCost_B!$D$17+UnitCost_B!$D$18)*Inputs!$B$36))/F$4) -> 0.68955509
A12: 민감도 — A 과제 매출총이익률: 과제당 케이스 수 × 단가
A13: 케이스 수 \ 단가(₩) | B13: 15000000 | C13: 20000000 | D13: 30000000 | E13: 40000000 | F13: 50000000
A14: 1 | B14: =IF(B$13=0,0,(B$13-($A14*UnitCost_A!$D$24+(Inputs!$B$42+Inputs!$B$43)*Inputs!$B$8*(1+Inputs!$B$36)))/B$13) -> 0.4040325 | C14: =IF(C$13=0,0,(C$13-($A14*UnitCost_A!$D$24+(Inputs!$B$42+Inputs!$B$43)*Inputs!$B$8*(1+Inputs!$B$36)))/C$13) -> 0.55302438 | D14: =IF(D$13=0,0,(D$13-($A14*UnitCost_A!$D$24+(Inputs!$B$42+Inputs!$B$43)*Inputs!$B$8*(1+Inputs!$B$36)))/D$13) -> 0.70201625 | E14: =IF(E$13=0,0,(E$13-($A14*UnitCost_A!$D$24+(Inputs!$B$42+Inputs!$B$43)*Inputs!$B$8*(1+Inputs!$B$36)))/E$13) -> 0.77651219 | F14: =IF(F$13=0,0,(F$13-($A14*UnitCost_A!$D$24+(Inputs!$B$42+Inputs!$B$43)*Inputs!$B$8*(1+Inputs!$B$36)))/F$13) -> 0.82120975
A15: 2 | B15: =IF(B$13=0,0,(B$13-($A15*UnitCost_A!$D$24+(Inputs!$B$42+Inputs!$B$43)*Inputs!$B$8*(1+Inputs!$B$36)))/B$13) -> 0.220565 | C15: =IF(C$13=0,0,(C$13-($A15*UnitCost_A!$D$24+(Inputs!$B$42+Inputs!$B$43)*Inputs!$B$8*(1+Inputs!$B$36)))/C$13) -> 0.41542375 | D15: =IF(D$13=0,0,(D$13-($A15*UnitCost_A!$D$24+(Inputs!$B$42+Inputs!$B$43)*Inputs!$B$8*(1+Inputs!$B$36)))/D$13) -> 0.6102825 | E15: =IF(E$13=0,0,(E$13-($A15*UnitCost_A!$D$24+(Inputs!$B$42+Inputs!$B$43)*Inputs!$B$8*(1+Inputs!$B$36)))/E$13) -> 0.70771187 | F15: =IF(F$13=0,0,(F$13-($A15*UnitCost_A!$D$24+(Inputs!$B$42+Inputs!$B$43)*Inputs!$B$8*(1+Inputs!$B$36)))/F$13) -> 0.7661695
A16: 3 | B16: =IF(B$13=0,0,(B$13-($A16*UnitCost_A!$D$24+(Inputs!$B$42+Inputs!$B$43)*Inputs!$B$8*(1+Inputs!$B$36)))/B$13) -> 0.0370975 | C16: =IF(C$13=0,0,(C$13-($A16*UnitCost_A!$D$24+(Inputs!$B$42+Inputs!$B$43)*Inputs!$B$8*(1+Inputs!$B$36)))/C$13) -> 0.27782313 | D16: =IF(D$13=0,0,(D$13-($A16*UnitCost_A!$D$24+(Inputs!$B$42+Inputs!$B$43)*Inputs!$B$8*(1+Inputs!$B$36)))/D$13) -> 0.51854875 | E16: =IF(E$13=0,0,(E$13-($A16*UnitCost_A!$D$24+(Inputs!$B$42+Inputs!$B$43)*Inputs!$B$8*(1+Inputs!$B$36)))/E$13) -> 0.63891156 | F16: =IF(F$13=0,0,(F$13-($A16*UnitCost_A!$D$24+(Inputs!$B$42+Inputs!$B$43)*Inputs!$B$8*(1+Inputs!$B$36)))/F$13) -> 0.71112925
A17: 5 | B17: =IF(B$13=0,0,(B$13-($A17*UnitCost_A!$D$24+(Inputs!$B$42+Inputs!$B$43)*Inputs!$B$8*(1+Inputs!$B$36)))/B$13) -> -0.3298375 | C17: =IF(C$13=0,0,(C$13-($A17*UnitCost_A!$D$24+(Inputs!$B$42+Inputs!$B$43)*Inputs!$B$8*(1+Inputs!$B$36)))/C$13) -> 0.002621875 | D17: =IF(D$13=0,0,(D$13-($A17*UnitCost_A!$D$24+(Inputs!$B$42+Inputs!$B$43)*Inputs!$B$8*(1+Inputs!$B$36)))/D$13) -> 0.33508125 | E17: =IF(E$13=0,0,(E$13-($A17*UnitCost_A!$D$24+(Inputs!$B$42+Inputs!$B$43)*Inputs!$B$8*(1+Inputs!$B$36)))/E$13) -> 0.50131094 | F17: =IF(F$13=0,0,(F$13-($A17*UnitCost_A!$D$24+(Inputs!$B$42+Inputs!$B$43)*Inputs!$B$8*(1+Inputs!$B$36)))/F$13) -> 0.60104875
A18: 8 | B18: =IF(B$13=0,0,(B$13-($A18*UnitCost_A!$D$24+(Inputs!$B$42+Inputs!$B$43)*Inputs!$B$8*(1+Inputs!$B$36)))/B$13) -> -0.88024 | C18: =IF(C$13=0,0,(C$13-($A18*UnitCost_A!$D$24+(Inputs!$B$42+Inputs!$B$43)*Inputs!$B$8*(1+Inputs!$B$36)))/C$13) -> -0.41018 | D18: =IF(D$13=0,0,(D$13-($A18*UnitCost_A!$D$24+(Inputs!$B$42+Inputs!$B$43)*Inputs!$B$8*(1+Inputs!$B$36)))/D$13) -> 0.05988 | E18: =IF(E$13=0,0,(E$13-($A18*UnitCost_A!$D$24+(Inputs!$B$42+Inputs!$B$43)*Inputs!$B$8*(1+Inputs!$B$36)))/E$13) -> 0.29491 | F18: =IF(F$13=0,0,(F$13-($A18*UnitCost_A!$D$24+(Inputs!$B$42+Inputs!$B$43)*Inputs!$B$8*(1+Inputs!$B$36)))/F$13) -> 0.435928
A21: 읽는 법: 음수 = 원가가 단가를 넘음. B에서 문서화 시간을 줄이는 것(템플릿 재사용)이 단가 인상과 같은 효과를 낸다.
